<?xml version="1.0" ?>
<!-- =================================================================================== -->
<!-- |    This document was autogenerated by xacro from /home/qiqi/test1/src/marm_description/urdf/arm.xacro | -->
<!-- |    EDITING THIS FILE BY HAND IS NOT RECOMMENDED                                 | -->
<!-- =================================================================================== -->
<robot name="arm">
    //定义一系列颜色
    <!-- Defining the colors used in this robot -->
    <material name="Black">
        <color rgba="0 0 0 1" />
    </material>
    <material name="White">
        <color rgba="1 1 1 1" />
    </material>
    <material name="Blue">
        <color rgba="0 0 1 1" />
    </material>
    <material name="Red">
        <color rgba="1 0 0 1" />
    </material>
    <!-- ///////////////////////////////////////   world  ////////////////////////////////////////// -->
    <link name="world" />
    <joint name="world_joint" type="fixed">
        <parent link="world" />
        <child link="base_link" />
        <origin rpy="0 0 0" xyz="0 0 0" />
    </joint>
    <!-- ///////////////////////////////////////   bottom_joint   ////////////////////////////////////////// -->
    <joint name="bottom_joint" type="fixed">
        <origin rpy="0 0 0" xyz="0 0 0" />
        <parent link="base_link" />
        <child link="bottom_link" />
    </joint>
    <link name="bottom_link">
        // 可视化
        <visual>
            <origin rpy="0 0 0" xyz=" 0 0 -0.02" />
            <geometry>
                <box size="1 1 0.02" />
            </geometry>
            <material name="silver">
                <color rgba=".8 .8 .8 1" />
            </material>
        </visual>
        // 碰撞属性
        <collision>
            <origin rpy="0 0 0" xyz=" 0 0 -0.02" />
            <geometry>
                <box size="1 1 0.02" />
            </geometry>
        </collision>
        <inertial>
            <origin rpy="0 0 0" xyz="0 0 0" />
            <mass value="500" />
            <inertia ixx="0.1" ixy="0" ixz="0" iyy="0.1" iyz="0" izz="0.1" />
        </inertial>
    </link>
    <!-- /////////////////////////////////////   BASE LINK    ////////////////////////////////////////////// -->
    <link name="base_link">
        <visual>
            <origin rpy="0 0 0" xyz="-0.035 0 0.025" />
            <geometry>
                <box size="0.165 0.085 0.05" />
            </geometry>
            <material name="White" />
        </visual>
        <inertial>
            <origin rpy="0 0 0" xyz="0 0 0.5" />
            <mass value="0.1" />
            <inertia ixx="0.1" ixy="0" ixz="0" iyy="0.1" iyz="0" izz="0.1" />
        </inertial>
        <collision>
            <origin rpy="0 0 0" xyz="-0.035 0 0.025" />
            <geometry>
                <box size="0.165 0.085 0.05" />
            </geometry>
        </collision>
    </link>
    <joint name="joint1" type="revolute">
        <parent link="base_link" />
        <child link="link1" />
        <origin rpy="0 0 0" xyz="0 0 0.05" />
        <axis xyz="0 0 1" />
        <limit effort="100" lower="-1.57" upper="1.57" velocity="100.0" />
        <dynamics damping="0.01" friction="0.0" />
    </joint>
    <!-- /////////////////////////////////////   LINK1  ////////////////////////////////////////////// -->
    <link name="link1">
        <visual>
            <origin rpy="0 0 0" xyz="0 0 0.05" />
            <geometry>
                <box size="0.08 0.065 0.1" />
            </geometry>
            <material name="Blue" />
        </visual>
        <inertial>
            <origin rpy="0 0 0" xyz="0 0 0" />
            <mass value="0.1" />
            <inertia ixx="0.1" ixy="0" ixz="0" iyy="0.1" iyz="0" izz="0.1" />
        </inertial>
        <collision>
            <origin rpy="0 0 0" xyz="0 0 0.05" />
            <geometry>
                <box size="0.08 0.065 0.1" />
            </geometry>
        </collision>
    </link>
    <joint name="joint2" type="revolute">
        <parent link="link1" />
        <child link="link2" />
        <origin rpy="0 2 0" xyz="0.03 0 0.075" />
        <axis xyz="0 -1 0" />
        <limit effort="100" lower="-1.57" upper="1.57" velocity="100.0" />
        <dynamics damping="0.01" friction="-1.0" />
    </joint>
    <!-- ///////////////////////////////////////   LINK2  ////////////////////////////////////////////// -->
    <link name="link2">
        <visual>
            <origin rpy="0 0 0" xyz="-0.06 0 0" />
            <geometry>
                <box size="0.12 0.03 0.02" />
            </geometry>
            <material name="White" />
        </visual>
        <inertial>
            <origin rpy="0 0 0" xyz="0 0 0" />
            <mass value="0.1" />
            <inertia ixx="0.1" ixy="0" ixz="0" iyy="0.1" iyz="0" izz="0.1" />
        </inertial>
        <collision>
            <origin rpy="0 0 0" xyz="-0.06 0 0" />
            <geometry>
                <box size="0.12 0.03 0.02" />
            </geometry>
        </collision>
    </link>
    <joint name="joint2m" type="revolute">
        <parent link="link2" />
        <child link="link2m" />
        <origin rpy="0 0 0" xyz="-0.12 0 0" />
        <axis xyz="0 -1 0" />
        <limit effort="100" lower="-1.57" upper="1.57" velocity="100.0" />
        <mimic joint="joint2" multiplier="-1" />
    </joint>
    <!-- /////////////////////////////////   LINK2m///////////////////////////////////////////////////// -->
    <link name="link2m">
        <interial>
            <origin rpy="0 0 0" xyz="0 0 0" />
            <mass value="0.1" />
            <interia ixx="0.1" ixy="0" ixz="0" iyy="0.1" iyz="0" izz="0.1" />
        </interial>
    </link>
    <joint name="joint3" type="revolute">
        <parent link="link2m" />
        <child link="link3" />
        <origin rpy="0 -1 0" xyz="0 0 0" />
        <axis xyz="0 1 0" />
        <limit effort="100" lower="-1.57" upper="1.57" velocity="100.0" />
        <dynamics damping="0.01" friction="0.0" />
    </joint>
    <!-- /////////////////////////////////   LINK3  ///////////////////////////////////////////////////// -->
    <link name="link3">
        <visual>
            <origin rpy="0 0 0" xyz="-0.025 0 0" />
            <geometry>
                <box size="0.04 0.045 0.06" />
            </geometry>
            <material name="Blue" />
        </visual>
        <inertial>
            <origin rpy="0 0 0" xyz="0.145 0 0" />
            <mass value="0.1" />
            <inertia ixx="0.1" ixy="0" ixz="0" iyy="0.1" iyz="0" izz="0.1" />
        </inertial>
        <collision>
            <origin rpy="0 0 0" xyz="-0.025 0 0" />
            <geometry>
                <box size="0.04 0.045 0.06" />
            </geometry>
        </collision>
    </link>
    <joint name="joint4" type="revolute">
        <parent link="link3" />
        <child link="link4" />
        <origin rpy="0 0 0" xyz="-0.025 0 0" />
        <axis xyz="0 0 1" />
        <limit effort="100" lower="-1.57" upper="1.57" velocity="100.0" />
        <dynamics damping="0.01" friction="0.0" />
    </joint>
    <!-- ///////////////////////////////////   LINK4  //////////////////////////////////////////////// -->
    <link name="link4">
        <visual>
            <origin rpy="0 0 0" xyz="0 0 0.1" />
            <geometry>
                <cylinder length="0.2" radius="0.01" />
            </geometry>
            <material name="Black" />
        </visual>
        <collision>
            <origin rpy="0 0 0" xyz="0 0 0.1" />
            <geometry>
                <cylinder length="0.2" radius="0.01" />
            </geometry>
        </collision>
        <inertial>
            <origin rpy="0 0 0" xyz="0 0 0" />
            <mass value="0.1" />
            <inertia ixx="0.1" ixy="0" ixz="0" iyy="0.1" iyz="0" izz="0.1" />
        </inertial>
    </link>
    <joint name="joint5" type="revolute">
        <parent link="link4" />
        <child link="link5" />
        <axis xyz="0 1 0" />
        <origin rpy="0 0 0" xyz="0 0 0.2" />
        <dynamics damping="0.01" friction="0.0" />
        <limit effort="100" lower="-1.57" upper="1.57" velocity="100.0" />
    </joint>
    <!-- //////////////////////////////////   LINK5  ///////////////////////////////////////////////// -->
    <link name="link5">
        <visual>
            <origin rpy="0 0 0" xyz="0.01 0 0" />
            <geometry>
                <box size="0.04 0.025 0.015" />
            </geometry>
            <material name="White" />
        </visual>
        <collision>
            <origin rpy="0 0 0" xyz="0.01 0 0" />
            <geometry>
                <box size="0.04 0.025 0.015" />
            </geometry>
        </collision>
        <inertial>
            <origin rpy="0 0 0" xyz="0 0 0.5" />
            <mass value="0.1" />
            <inertia ixx="0.1" ixy="0" ixz="0" iyy="0.1" iyz="0" izz="0.1" />
        </inertial>
    </link>
    <joint name="joint6" type="revolute">
        <parent link="link5" />
        <child link="link6" />
        <axis xyz="0 0 1" />
        <origin rpy="0 0 0" xyz="0 0 0.015" />
        <dynamics damping="0.01" friction="0.0" />
        <limit effort="100" lower="-1.57" upper="1.57" velocity="100.0" />
    </joint>
    <!-- ////////////////////////////////   LINK6  ///////////////////////////////////////////////// -->
    <link name="link6">
        <visual>
            <origin rpy="0 0 0" xyz="0 0 0" />
            <geometry>
                <cylinder length="0.003" radius="0.015" />
            </geometry>
            <material name="Blue" />
        </visual>
        <collision>
            <origin rpy="0 0 0" xyz="0 0 0" />
            <geometry>
                <cylinder length="0.003" radius="0.015" />
            </geometry>
        </collision>
        <inertial>
            <origin rpy="0 0 0" xyz="0 0 0.5" />
            <mass value="0.1" />
            <inertia ixx="0.1" ixy="0" ixz="0" iyy="0.1" iyz="0" izz="0.1" />
        </inertial>
    </link>
    <joint name="pen_joint" type="fixed">
        <parent link="link6" />
        <child link="pen" />
    </joint>
    <!-- //////////////////////////////////////   pen   ////////////////////////////////////////////// -->
    <link name="pen">
        <visual>
            <origin rpy="0 1.7 0" xyz="0.08 0 0" />
            <geometry>
                <cylinder length="0.16" radius="0.008" />
            </geometry>
            <material name="White" />
        </visual>
        <inertial>
            <origin rpy="0 1.7 0" xyz="0.08 0 0" />
            <mass value="0.1" />
            <inertia ixx="0.1" ixy="0" ixz="0" iyy="0.1" iyz="0" izz="0.1" />
        </inertial>
        <collision>
            <origin rpy="0 1.7 0" xyz="0.08 0 0" />
            <geometry>
                <cylinder length="0.16" radius="0.008" />
            </geometry>
        </collision>
    </link>
    <!-- //////////////////////////////////////   pen_tip  ////////////////////////////////////////////// -->
    <link name="pen_tip">
        <visual>
            <origin rpy="0 0 0" xyz="0 0 0" />
            <geometry>
                <sphere radius="0.008" />
            </geometry>
            <material name="Red" />
        </visual>
        <collision>
            <origin rpy="0 0 0" xyz="0 0 0" />
            <geometry>
                <sphere radius="0.008" />
            </geometry>
        </collision>
        <inertial>
            <origin rpy="0 0 0" xyz="0 0 0" />
            <mass value="0.1" />
            <inertia ixx="0.1" ixy="0" ixz="0" iyy="0.1" iyz="0" izz="0.1" />
        </inertial>
    </link>
    <joint name="pen_tip_joint" type="fixed">
        <parent link="pen" />
        <child link="pen_tip" />
        <origin rpy="0 0 0" xyz="0.16 0 -0.008" />
    </joint>
    <!-- /////////////////////////////////   Gazebo   ////////////////////////////////////// -->
    <gazebo reference="bottom_link">
        <material>Gazebo/White</material>
        <plugin name="gazebo_ros_control">
            <robotNamespace>/</robotNamespace>
        </plugin>
    </gazebo>
    <gazebo reference="base_link">
        <material>Gazebo/White</material>
    </gazebo>
    <gazebo reference="link1">
        <material>Gazebo/Blue</material>
    </gazebo>
    <gazebo reference="link2">
        <material>Gazebo/White</material>
    </gazebo>
    <gazebo reference="link2m">
        <material>Gazebo/White</material>
    </gazebo>    
    <gazebo reference="link3">
        <material>Gazebo/Blue</material>
    </gazebo>
    <gazebo reference="link4">
        <material>Gazebo/Black</material>
    </gazebo>
    <gazebo reference="link5">
        <material>Gazebo/White</material>
    </gazebo>
    <gazebo reference="link6">
        <material>Gazebo/Blue</material>
    </gazebo>
    <gazebo reference="pen">
        <material>Gazebo/White</material>
    </gazebo>
    <gazebo reference="pen_tip_joint">
        <material>Gazebo/Blue</material>
    </gazebo>
    <transmission name="tran1">
        <type>transmission_interface/SimpleTransmission</type>
        <joint name="joint1">
            <hardwareInterface>hardware_interface/PositionJointInterface</hardwareInterface>
        </joint>
        <actuator name="motor1">
            <hardwareInterface>hardware_interface/PositionJointInterface</hardwareInterface>
            <mechanicalReduction>1</mechanicalReduction>
        </actuator>
    </transmission>
    <transmission name="tran2">
        <type>transmission_interface/SimpleTransmission</type>
        <joint name="joint2">
            <hardwareInterface>hardware_interface/PositionJointInterface</hardwareInterface>
        </joint>
        <actuator name="motor2">
            <hardwareInterface>hardware_interface/PositionJointInterface</hardwareInterface>
            <mechanicalReduction>1</mechanicalReduction>
        </actuator>
    </transmission>
    <transmission name="tran2m">
        <type>transmission_interface/SimpleTransmission</type>
        <joint name="joint2m">
            <hardwareInterface>hardware_interface/PositionJointInterface</hardwareInterface>
        </joint>
        <actuator name="motor2m">
            <hardwareInterface>hardware_interface/PositionJointInterface</hardwareInterface>
            <mechanicalReduction>1</mechanicalReduction>
        </actuator>
    </transmission>
    <transmission name="tran3">
        <type>transmission_interface/SimpleTransmission</type>
        <joint name="joint3">
            <hardwareInterface>hardware_interface/PositionJointInterface</hardwareInterface>
        </joint>
        <actuator name="motor3">
            <hardwareInterface>hardware_interface/PositionJointInterface</hardwareInterface>
            <mechanicalReduction>1</mechanicalReduction>
        </actuator>
    </transmission>
    <transmission name="tran4">
        <type>transmission_interface/SimpleTransmission</type>
        <joint name="joint4">
            <hardwareInterface>hardware_interface/PositionJointInterface</hardwareInterface>
        </joint>
        <actuator name="motor4">
            <hardwareInterface>hardware_interface/PositionJointInterface</hardwareInterface>
            <mechanicalReduction>1</mechanicalReduction>
        </actuator>
    </transmission>
    <transmission name="tran5">
        <type>transmission_interface/SimpleTransmission</type>
        <joint name="joint5">
            <hardwareInterface>hardware_interface/PositionJointInterface</hardwareInterface>
        </joint>
        <actuator name="motor5">
            <hardwareInterface>hardware_interface/PositionJointInterface</hardwareInterface>
            <mechanicalReduction>1</mechanicalReduction>
        </actuator>
    </transmission>
    <transmission name="tran6">
        <type>transmission_interface/SimpleTransmission</type>
        <joint name="joint6">
            <hardwareInterface>hardware_interface/PositionJointInterface</hardwareInterface>
        </joint>
        <actuator name="motor6">
            <hardwareInterface>hardware_interface/PositionJointInterface</hardwareInterface>
            <mechanicalReduction>1</mechanicalReduction>
        </actuator>
    </transmission>
    <!-- ros_control plugin -->
    <gazebo>
        <plugin filename="libgazebo_ros_control.so" name="gazebo_ros_control">
            <robotNamespace>/arm</robotNamespace>
        </plugin>
    </gazebo>
</robot>

